<?xml version="1.0"?>
<robot name="my_robot">
  <!-- TODO: Create a base_link with visual, collision, and inertial properties -->
  <link name="base_link">
    <visual>
      <geometry>
        <box size="0.4 0.3 0.1"/>
      </geometry>
      <material name="blue">
        <color rgba="0 0 0.8 1"/>
      </material>
    </visual>
    <collision>
      <geometry>
        <box size="0.4 0.3 0.1"/>
      </geometry>
    </collision>
    <inertial>
      <mass value="1.0"/>
      <origin xyz="0 0 0" rpy="0 0 0"/>
      <inertia ixx="0.01" ixy="0.0" ixz="0.0" iyy="0.01" iyz="0.0" izz="0.01"/>
    </inertial>
  </link>

  <!-- Add cillinder on top of the robot-->
  <link name="top_link">
    <visual>
      <geometry>
        <cylinder radius="0.1" length="0.07"/>
      </geometry>
      <material name="yellow">
        <color rgba="0.8 0.8 0.0 1"/>
      </material>
    </visual>
    <collision>
      <geometry>
        <cylinder radius="0.1" length="0.07"/>
      </geometry>
    </collision>
    <inertial>
      <mass value="1.0"/>
      <origin xyz="0 0 0" rpy="0 0 0"/>
      <inertia ixx="0.01" ixy="0.0" ixz="0.0" iyy="0.01" iyz="0.0" izz="0.01"/>
    </inertial>
  </link>
  
  <!-- Right Wheel -->
  <link name="right_wheel">
    <visual>
      <!-- Use cylinder that's SHORTER but WIDER to show the correct orientation -->
      <geometry>
        <cylinder radius="0.08" length="0.05"/>
      </geometry>
      <material name="black">
        <color rgba="0 0 0 1"/>
      </material>
      <!-- No rotation, leaving it flat -->
      <origin xyz="0 0 0" rpy="0 0 0"/>
    </visual>
    <collision>
      <geometry>
        <cylinder radius="0.08" length="0.05"/>
      </geometry>
      <origin xyz="0 0 0" rpy="0 0 0"/>
    </collision>
    <inertial>
      <mass value="0.1"/>
      <origin xyz="0 0 0" rpy="0 0 0"/>
      <inertia ixx="0.00015" ixy="0.0" ixz="0.0" iyy="0.00015" iyz="0.0" izz="0.0001"/>
    </inertial>
  </link>

  <!-- Left Wheel -->
  <link name="left_wheel">
    <visual>
      <!-- Use cylinder that's SHORTER but WIDER to show the correct orientation -->
      <geometry>
        <cylinder radius="0.08" length="0.05"/>
      </geometry>
      <material name="black">
        <color rgba="0 0 0 1"/>
      </material>
      <!-- No rotation, leaving it flat -->
      <origin xyz="0 0 0" rpy="0 0 0"/>
    </visual>
    <collision>
      <geometry>
        <cylinder radius="0.08" length="0.05"/>
      </geometry>
      <origin xyz="0 0 0" rpy="0 0 0"/>
    </collision>
    <inertial>
      <mass value="0.1"/>
      <origin xyz="0 0 0" rpy="0 0 0"/>
      <inertia ixx="0.00015" ixy="0.0" ixz="0.0" iyy="0.00015" iyz="0.0" izz="0.0001"/>
    </inertial>
  </link>

  <!-- Caster Wheel -->
  <link name="caster_wheel">
    <visual>
      <geometry>
        <sphere radius="0.035"/>
      </geometry>
      <material name="grey">
        <color rgba="0.5 0.5 0.5 1"/>
      </material>
    </visual>
    <collision>
      <geometry>
        <sphere radius="0.035"/>
      </geometry>
    </collision>
    <inertial>
      <mass value="0.05"/>
      <origin xyz="0 0 0" rpy="0 0 0"/>
      <inertia ixx="0.00002" ixy="0.0" ixz="0.0" iyy="0.00002" iyz="0.0" izz="0.00002"/>
    </inertial>
  </link>

  <joint name="top_link_joint" type="fixed">
    <parent link="base_link"/>
    <child link="top_link"/>
    <origin xyz="0 0 0.085" rpy="0 0 0"/>
  </joint>

  <!-- Right Wheel Joint -->
  <joint name="right_wheel_joint" type="continuous">
    <parent link="base_link"/>
    <child link="right_wheel"/>
    <!-- Position the wheel on its edge -->
    <origin xyz="-0.15 -0.17 0" rpy="1.5707 0 0"/>
    <!-- Rotate around Z axis as viewed from wheel's perspective -->
    <axis xyz="0 0 -1"/>
    <dynamics damping="0.01" friction="0.0"/>
  </joint>

  <!-- Left Wheel Joint -->
  <joint name="left_wheel_joint" type="continuous">
    <parent link="base_link"/>
    <child link="left_wheel"/>
    <!-- Position the wheel on its edge -->
    <origin xyz="-0.15 0.17 0" rpy="1.5707 0 0"/>
    <!-- Rotate around Z axis as viewed from wheel's perspective -->
    <axis xyz="0 0 -1"/>
    <dynamics damping="0.01" friction="0.0"/>
  </joint>

  <!-- Caster Joint -->
  <joint name="caster_joint" type="fixed">
    <parent link="base_link"/>
    <child link="caster_wheel"/>
    <origin xyz="0.12 0 -0.0325" rpy="0 0 0"/>
  </joint>

  <!-- TODO: Create 3D Lidar link -->

  <link name="lidar_link">
    <visual>
      <geometry>
        <cylinder radius="0.05" length="0.02"/>
      </geometry>
      <material name="grey">
        <color rgba="0.5 0.5 0.5 1"/>
      </material>
    </visual>
    <collision>
      <geometry>
        <cylinder radius="0.05" length="0.02"/>
      </geometry>
    </collision>
    <inertial>
      <mass value="0.1"/>
      <origin xyz="0 0 0" rpy="0 0 0"/>
      <inertia ixx="0.0001" ixy="0" ixz="0" iyy="0.0001" iyz="0" izz="0.0001"/>
    </inertial>
  </link>

  <joint name="lidar_joint" type="fixed">
    <parent link="base_link"/>
    <child link="lidar_link"/>
    <!-- Position the LiDAR on top of the robot -->
    <origin xyz="0 0 0.15" rpy="0 0 0"/>
  </joint>


  <!-- TODO: Add Gazebo material colours for all links -->

  <gazebo reference="base_link">
    <material>Gazebo/Blue</material>
  </gazebo>
  <gazebo reference="right_wheel">
    <material>Gazebo/Black</material>
    <mu1>1.0</mu1>
    <mu2>1.0</mu2>
  </gazebo>
  <gazebo reference="left_wheel">
    <material>Gazebo/Black</material>
    <mu1>1.0</mu1>
    <mu2>1.0</mu2>
  </gazebo>
  <gazebo reference="caster_wheel">
    <material>Gazebo/Grey</material>
    <mu1>0.1</mu1>
    <mu2>0.1</mu2>
  </gazebo>

  <gazebo reference="lidar_link">
    <material>Gazebo/Grey</material>
  </gazebo>

  <gazebo reference="top_link">
    <material>Gazebo/Yellow</material>
  </gazebo>

  <!-- TODO: Add Gazebo plugins for:
       - Joint state publisher
       - Pose publisher
       - Differential drive controller
  -->

  <gazebo>
     <!-- Joint state publisher for Gazebo Harmonic -->
     <plugin filename="libgz-sim-joint-state-publisher-system.so"
             name="gz::sim::systems::JointStatePublisher">
      <joint_name>left_wheel_joint</joint_name>
      <joint_name>right_wheel_joint</joint_name>
      <update_rate>20</update_rate>
    </plugin>

    <!-- Pose publisher plugin -->
    <plugin filename="libgz-sim-pose-publisher-system.so"
            name="gz::sim::systems::PosePublisher">
      <publish_link_pose>true</publish_link_pose>
      <publish_collision_pose>false</publish_collision_pose>
      <publish_visual_pose>false</publish_visual_pose>
      <publish_nested_model_pose>true</publish_nested_model_pose>
      <update_rate>20</update_rate>
    </plugin>

    <!-- Differential drive plugin for Gazebo Harmonic -->
    <plugin filename="libgz-sim-diff-drive-system.so"
            name="gz::sim::systems::DiffDrive">
      <left_joint>left_wheel_joint</left_joint>
      <right_joint>right_wheel_joint</right_joint>
      <wheel_separation>0.34</wheel_separation>
      <wheel_radius>0.08</wheel_radius>
      <odom_publish_frequency>20</odom_publish_frequency>
      <topic>cmd_vel</topic>
      <frame_id>odom</frame_id>
      <child_frame_id>base_link</child_frame_id>
    </plugin>

    <plugin filename="libgz-sim-gpu-lidar-system.so" 
          name="gz::sim::systems::GpuLidar"/>
      <topic>lidar/points</topic>
      <frame_id>lidar_link</frame_id>
      <horizontal_samples>720</horizontal_samples>
      <horizontal_resolution>1</horizontal_resolution>
      <horizontal_min_angle>-3.14159</horizontal_min_angle>  <!-- 360 degrees -->
      <horizontal_max_angle>3.14159</horizontal_max_angle>
      <vertical_samples>16</vertical_samples>
      <vertical_resolution>1</vertical_resolution>
      <vertical_min_angle>-0.261799</vertical_min_angle>  <!-- ~-15 degrees -->
      <vertical_max_angle>0.261799</vertical_max_angle>   <!-- ~+15 degrees -->
      <range_min>0.1</range_min>
      <range_max>30.0</range_max>
      <range_resolution>0.01</range_resolution>

    </plugin>


  </gazebo>

  <!-- TODO: Add Lidar sensor -->

  <gazebo reference="lidar_link">
    <sensor name="lidar_sensor" type="lidar">
      <update_rate>10.0</update_rate>
      <pose>0 0 0 0 0 0</pose>
      <ray>
        <scan>
          <horizontal>
            <samples>720</samples>
            <resolution>1</resolution>
            <min_angle>-3.14159</min_angle>  <!-- 360 degrees -->
            <max_angle>3.14159</max_angle>
          </horizontal>
          <vertical>
            <samples>16</samples>
            <resolution>1</resolution>
            <min_angle>-0.261799</min_angle>  <!-- ~-15 degrees -->
            <max_angle>0.261799</max_angle>   <!-- ~+15 degrees -->
          </vertical>
        </scan>
        <range>
          <min>0.1</min>
          <max>30.0</max>
          <resolution>0.01</resolution>
        </range>
      </ray>
    </sensor>
  </gazebo>


</robot>